2025-10-14 11:07:30,531 INFO    MainThread:32592 [wandb_setup.py:_flush():81] Current SDK version is 0.22.2
2025-10-14 11:07:30,531 INFO    MainThread:32592 [wandb_setup.py:_flush():81] Configure stats pid to 32592
2025-10-14 11:07:30,531 INFO    MainThread:32592 [wandb_setup.py:_flush():81] Loading settings from C:\Users\trexx\.config\wandb\settings
2025-10-14 11:07:30,531 INFO    MainThread:32592 [wandb_setup.py:_flush():81] Loading settings from D:\Code\Machine Learning\indonesian_coconut\wandb\settings
2025-10-14 11:07:30,531 INFO    MainThread:32592 [wandb_setup.py:_flush():81] Loading settings from environment variables
2025-10-14 11:07:30,531 INFO    MainThread:32592 [wandb_init.py:setup_run_log_directory():705] Logging user logs to D:\Code\Machine Learning\indonesian_coconut\wandb\run-20251014_110730-rbk1n1z5\logs\debug.log
2025-10-14 11:07:30,535 INFO    MainThread:32592 [wandb_init.py:setup_run_log_directory():706] Logging internal logs to D:\Code\Machine Learning\indonesian_coconut\wandb\run-20251014_110730-rbk1n1z5\logs\debug-internal.log
2025-10-14 11:07:30,535 INFO    MainThread:32592 [wandb_init.py:init():832] calling init triggers
2025-10-14 11:07:30,535 INFO    MainThread:32592 [wandb_init.py:init():837] wandb.init called with sweep_config: {}
config: {'n_proc': 32, 'min_inference_size': 29, 'timestep_limit': 1000000000, 'exp_buffer_size': 150000, 'ts_per_iteration': 50000, 'standardize_returns': True, 'standardize_obs': False, 'policy_layer_sizes': (256, 256, 256), 'critic_layer_sizes': (256, 256, 256), 'ppo_epochs': 1, 'ppo_batch_size': 50000, 'ppo_minibatch_size': 50000, 'ppo_ent_coef': 0.001, 'ppo_clip_range': 0.2, 'gae_lambda': 0.95, 'gae_gamma': 0.99, 'policy_lr': 0.0003, 'critic_lr': 0.0003, 'shm_buffer_size': 8192, '_wandb': {}}
2025-10-14 11:07:30,535 INFO    MainThread:32592 [wandb_init.py:init():880] starting backend
2025-10-14 11:07:33,038 INFO    MainThread:32592 [wandb_init.py:init():883] sending inform_init request
2025-10-14 11:07:33,110 INFO    MainThread:32592 [wandb_init.py:init():891] backend started and connected
2025-10-14 11:07:33,112 INFO    MainThread:32592 [wandb_init.py:init():961] updated telemetry
2025-10-14 11:07:33,114 INFO    MainThread:32592 [wandb_init.py:init():985] communicating run to backend with 90.0 second timeout
2025-10-14 11:07:34,241 INFO    MainThread:32592 [wandb_init.py:init():1036] starting run threads in backend
2025-10-14 11:07:34,809 INFO    MainThread:32592 [wandb_run.py:_console_start():2509] atexit reg
2025-10-14 11:07:34,809 INFO    MainThread:32592 [wandb_run.py:_redirect():2357] redirect: wrap_raw
2025-10-14 11:07:34,809 INFO    MainThread:32592 [wandb_run.py:_redirect():2426] Wrapping output streams.
2025-10-14 11:07:34,809 INFO    MainThread:32592 [wandb_run.py:_redirect():2449] Redirects installed.
2025-10-14 11:07:34,831 INFO    MainThread:32592 [wandb_init.py:init():1076] run started, returning control to user process
2025-10-14 11:07:43,330 ERROR   wandb-AsyncioManager-main:32592 [service_client.py:_forward_responses():77] Error reading server response.
Traceback (most recent call last):
  File "C:\Program Files\WindowsApps\PythonSoftwareFoundation.Python.3.12_3.12.2800.0_x64__qbz5n2kfra8p0\Lib\asyncio\windows_events.py", line 462, in finish_socket_func
    return ov.getresult()
           ^^^^^^^^^^^^^^
OSError: [WinError 64] The specified network name is no longer available

During handling of the above exception, another exception occurred:

Traceback (most recent call last):
  File "D:\Code\Machine Learning\indonesian_coconut\venv\Lib\site-packages\wandb\sdk\lib\service\service_client.py", line 73, in _forward_responses
    while response := await self._read_server_response():
                      ^^^^^^^^^^^^^^^^^^^^^^^^^^^^^^^^^^
  File "D:\Code\Machine Learning\indonesian_coconut\venv\Lib\site-packages\wandb\sdk\lib\service\service_client.py", line 87, in _read_server_response
    header = await self._reader.readexactly(_HEADER_BYTE_INT_LEN)
             ^^^^^^^^^^^^^^^^^^^^^^^^^^^^^^^^^^^^^^^^^^^^^^^^^^^^
  File "C:\Program Files\WindowsApps\PythonSoftwareFoundation.Python.3.12_3.12.2800.0_x64__qbz5n2kfra8p0\Lib\asyncio\streams.py", line 752, in readexactly
    await self._wait_for_data('readexactly')
  File "C:\Program Files\WindowsApps\PythonSoftwareFoundation.Python.3.12_3.12.2800.0_x64__qbz5n2kfra8p0\Lib\asyncio\streams.py", line 545, in _wait_for_data
    await self._waiter
  File "C:\Program Files\WindowsApps\PythonSoftwareFoundation.Python.3.12_3.12.2800.0_x64__qbz5n2kfra8p0\Lib\asyncio\proactor_events.py", line 286, in _loop_reading
    length = fut.result()
             ^^^^^^^^^^^^
  File "C:\Program Files\WindowsApps\PythonSoftwareFoundation.Python.3.12_3.12.2800.0_x64__qbz5n2kfra8p0\Lib\asyncio\windows_events.py", line 803, in _poll
    value = callback(transferred, key, ov)
            ^^^^^^^^^^^^^^^^^^^^^^^^^^^^^^
  File "C:\Program Files\WindowsApps\PythonSoftwareFoundation.Python.3.12_3.12.2800.0_x64__qbz5n2kfra8p0\Lib\asyncio\windows_events.py", line 466, in finish_socket_func
    raise ConnectionResetError(*exc.args)
ConnectionResetError: [WinError 64] The specified network name is no longer available
2025-10-14 11:07:43,349 INFO    wandb-AsyncioManager-main:32592 [mailbox.py:close():137] Closing mailbox, abandoning 1 handles.
2025-10-14 11:07:44,672 ERROR   MainThread:32592 [redirect.py:_on_write():664] [all runs] error in stdout callback
Traceback (most recent call last):
  File "D:\Code\Machine Learning\indonesian_coconut\venv\Lib\site-packages\rlgym_ppo\learner.py", line 225, in learn
    self._learn()
  File "D:\Code\Machine Learning\indonesian_coconut\venv\Lib\site-packages\rlgym_ppo\learner.py", line 270, in _learn
    ppo_report = self.ppo_learner.learn(self.experience_buffer)
                 ^^^^^^^^^^^^^^^^^^^^^^^^^^^^^^^^^^^^^^^^^^^^^^
  File "D:\Code\Machine Learning\indonesian_coconut\venv\Lib\site-packages\rlgym_ppo\ppo\ppo_learner.py", line 179, in learn
    ppo_loss.backward()
  File "D:\Code\Machine Learning\indonesian_coconut\venv\Lib\site-packages\torch\_tensor.py", line 647, in backward
    torch.autograd.backward(
  File "D:\Code\Machine Learning\indonesian_coconut\venv\Lib\site-packages\torch\autograd\__init__.py", line 354, in backward
    _engine_run_backward(
  File "D:\Code\Machine Learning\indonesian_coconut\venv\Lib\site-packages\torch\autograd\graph.py", line 829, in _engine_run_backward
    return Variable._execution_engine.run_backward(  # Calls into the C++ engine to run the backward pass
           ^^^^^^^^^^^^^^^^^^^^^^^^^^^^^^^^^^^^^^^^^^^^^^^^^^^^^^^^^^^^^^^^^^^^^^^^^^^^^^^^^^^^^^^^^^^^^^
torch.AcceleratorError: CUDA error: unknown error
CUDA kernel errors might be asynchronously reported at some other API call, so the stacktrace below might be incorrect.
For debugging consider passing CUDA_LAUNCH_BLOCKING=1
Compile with `TORCH_USE_CUDA_DSA` to enable device-side assertions.


During handling of the above exception, another exception occurred:

Traceback (most recent call last):
  File "D:\Code\Machine Learning\indonesian_coconut\venv\Lib\site-packages\wandb\sdk\lib\redirect.py", line 662, in _on_write
    cb(written_data)
  File "D:\Code\Machine Learning\indonesian_coconut\venv\Lib\site-packages\wandb\sdk\wandb_run.py", line 2430, in <lambda>
    lambda data: self._console_raw_callback("stdout", data),
                 ^^^^^^^^^^^^^^^^^^^^^^^^^^^^^^^^^^^^^^^^^^
  File "D:\Code\Machine Learning\indonesian_coconut\venv\Lib\site-packages\wandb\sdk\wandb_run.py", line 399, in wrapper
    return func(self, *args, **kwargs)
           ^^^^^^^^^^^^^^^^^^^^^^^^^^^
  File "D:\Code\Machine Learning\indonesian_coconut\venv\Lib\site-packages\wandb\sdk\wandb_run.py", line 457, in wrapper_fn
    return func(self, *args, **kwargs)
           ^^^^^^^^^^^^^^^^^^^^^^^^^^^
  File "D:\Code\Machine Learning\indonesian_coconut\venv\Lib\site-packages\wandb\sdk\wandb_run.py", line 1595, in _console_raw_callback
    self._backend.interface.publish_output_raw(name, data)
  File "D:\Code\Machine Learning\indonesian_coconut\venv\Lib\site-packages\wandb\sdk\interface\interface.py", line 802, in publish_output_raw
    self._publish_output_raw(o)
  File "D:\Code\Machine Learning\indonesian_coconut\venv\Lib\site-packages\wandb\sdk\interface\interface_shared.py", line 37, in _publish_output_raw
    self._publish(rec)
  File "D:\Code\Machine Learning\indonesian_coconut\venv\Lib\site-packages\wandb\sdk\interface\interface_sock.py", line 43, in _publish
    self._asyncer.run(lambda: self._client.publish(request))
  File "D:\Code\Machine Learning\indonesian_coconut\venv\Lib\site-packages\wandb\sdk\lib\asyncio_manager.py", line 136, in run
    return future.result()
           ^^^^^^^^^^^^^^^
  File "C:\Program Files\WindowsApps\PythonSoftwareFoundation.Python.3.12_3.12.2800.0_x64__qbz5n2kfra8p0\Lib\concurrent\futures\_base.py", line 449, in result
    return self.__get_result()
           ^^^^^^^^^^^^^^^^^^^
  File "C:\Program Files\WindowsApps\PythonSoftwareFoundation.Python.3.12_3.12.2800.0_x64__qbz5n2kfra8p0\Lib\concurrent\futures\_base.py", line 401, in __get_result
    raise self._exception
  File "D:\Code\Machine Learning\indonesian_coconut\venv\Lib\site-packages\wandb\sdk\lib\asyncio_manager.py", line 219, in _wrap
    return await fn()
           ^^^^^^^^^^
  File "D:\Code\Machine Learning\indonesian_coconut\venv\Lib\site-packages\wandb\sdk\lib\service\service_client.py", line 38, in publish
    await self._send_server_request(request)
  File "D:\Code\Machine Learning\indonesian_coconut\venv\Lib\site-packages\wandb\sdk\lib\service\service_client.py", line 64, in _send_server_request
    await self._writer.drain()
  File "C:\Program Files\WindowsApps\PythonSoftwareFoundation.Python.3.12_3.12.2800.0_x64__qbz5n2kfra8p0\Lib\asyncio\streams.py", line 380, in drain
    raise exc
  File "D:\Code\Machine Learning\indonesian_coconut\venv\Lib\site-packages\wandb\sdk\lib\service\service_client.py", line 73, in _forward_responses
    while response := await self._read_server_response():
                      ^^^^^^^^^^^^^^^^^^^^^^^^^^^^^^^^^^
  File "D:\Code\Machine Learning\indonesian_coconut\venv\Lib\site-packages\wandb\sdk\lib\service\service_client.py", line 87, in _read_server_response
    header = await self._reader.readexactly(_HEADER_BYTE_INT_LEN)
             ^^^^^^^^^^^^^^^^^^^^^^^^^^^^^^^^^^^^^^^^^^^^^^^^^^^^
  File "C:\Program Files\WindowsApps\PythonSoftwareFoundation.Python.3.12_3.12.2800.0_x64__qbz5n2kfra8p0\Lib\asyncio\streams.py", line 752, in readexactly
    await self._wait_for_data('readexactly')
  File "C:\Program Files\WindowsApps\PythonSoftwareFoundation.Python.3.12_3.12.2800.0_x64__qbz5n2kfra8p0\Lib\asyncio\streams.py", line 545, in _wait_for_data
    await self._waiter
  File "C:\Program Files\WindowsApps\PythonSoftwareFoundation.Python.3.12_3.12.2800.0_x64__qbz5n2kfra8p0\Lib\asyncio\proactor_events.py", line 286, in _loop_reading
    length = fut.result()
             ^^^^^^^^^^^^
  File "C:\Program Files\WindowsApps\PythonSoftwareFoundation.Python.3.12_3.12.2800.0_x64__qbz5n2kfra8p0\Lib\asyncio\windows_events.py", line 803, in _poll
    value = callback(transferred, key, ov)
            ^^^^^^^^^^^^^^^^^^^^^^^^^^^^^^
  File "C:\Program Files\WindowsApps\PythonSoftwareFoundation.Python.3.12_3.12.2800.0_x64__qbz5n2kfra8p0\Lib\asyncio\windows_events.py", line 466, in finish_socket_func
    raise ConnectionResetError(*exc.args)
ConnectionResetError: [WinError 64] The specified network name is no longer available
2025-10-14 11:07:44,879 ERROR   MainThread:32592 [redirect.py:_on_write():664] [all runs] error in stdout callback
Traceback (most recent call last):
  File "D:\Code\Machine Learning\indonesian_coconut\venv\Lib\site-packages\rlgym_ppo\learner.py", line 225, in learn
    self._learn()
  File "D:\Code\Machine Learning\indonesian_coconut\venv\Lib\site-packages\rlgym_ppo\learner.py", line 270, in _learn
    ppo_report = self.ppo_learner.learn(self.experience_buffer)
                 ^^^^^^^^^^^^^^^^^^^^^^^^^^^^^^^^^^^^^^^^^^^^^^
  File "D:\Code\Machine Learning\indonesian_coconut\venv\Lib\site-packages\rlgym_ppo\ppo\ppo_learner.py", line 179, in learn
    ppo_loss.backward()
  File "D:\Code\Machine Learning\indonesian_coconut\venv\Lib\site-packages\torch\_tensor.py", line 647, in backward
    torch.autograd.backward(
  File "D:\Code\Machine Learning\indonesian_coconut\venv\Lib\site-packages\torch\autograd\__init__.py", line 354, in backward
    _engine_run_backward(
  File "D:\Code\Machine Learning\indonesian_coconut\venv\Lib\site-packages\torch\autograd\graph.py", line 829, in _engine_run_backward
    return Variable._execution_engine.run_backward(  # Calls into the C++ engine to run the backward pass
           ^^^^^^^^^^^^^^^^^^^^^^^^^^^^^^^^^^^^^^^^^^^^^^^^^^^^^^^^^^^^^^^^^^^^^^^^^^^^^^^^^^^^^^^^^^^^^^
torch.AcceleratorError: CUDA error: unknown error
CUDA kernel errors might be asynchronously reported at some other API call, so the stacktrace below might be incorrect.
For debugging consider passing CUDA_LAUNCH_BLOCKING=1
Compile with `TORCH_USE_CUDA_DSA` to enable device-side assertions.


During handling of the above exception, another exception occurred:

Traceback (most recent call last):
  File "D:\Code\Machine Learning\indonesian_coconut\venv\Lib\site-packages\wandb\sdk\lib\redirect.py", line 662, in _on_write
    cb(written_data)
  File "D:\Code\Machine Learning\indonesian_coconut\venv\Lib\site-packages\wandb\sdk\wandb_run.py", line 2430, in <lambda>
    lambda data: self._console_raw_callback("stdout", data),
                 ^^^^^^^^^^^^^^^^^^^^^^^^^^^^^^^^^^^^^^^^^^
  File "D:\Code\Machine Learning\indonesian_coconut\venv\Lib\site-packages\wandb\sdk\wandb_run.py", line 399, in wrapper
    return func(self, *args, **kwargs)
           ^^^^^^^^^^^^^^^^^^^^^^^^^^^
  File "D:\Code\Machine Learning\indonesian_coconut\venv\Lib\site-packages\wandb\sdk\wandb_run.py", line 457, in wrapper_fn
    return func(self, *args, **kwargs)
           ^^^^^^^^^^^^^^^^^^^^^^^^^^^
  File "D:\Code\Machine Learning\indonesian_coconut\venv\Lib\site-packages\wandb\sdk\wandb_run.py", line 1595, in _console_raw_callback
    self._backend.interface.publish_output_raw(name, data)
  File "D:\Code\Machine Learning\indonesian_coconut\venv\Lib\site-packages\wandb\sdk\interface\interface.py", line 802, in publish_output_raw
    self._publish_output_raw(o)
  File "D:\Code\Machine Learning\indonesian_coconut\venv\Lib\site-packages\wandb\sdk\interface\interface_shared.py", line 37, in _publish_output_raw
    self._publish(rec)
  File "D:\Code\Machine Learning\indonesian_coconut\venv\Lib\site-packages\wandb\sdk\interface\interface_sock.py", line 43, in _publish
    self._asyncer.run(lambda: self._client.publish(request))
  File "D:\Code\Machine Learning\indonesian_coconut\venv\Lib\site-packages\wandb\sdk\lib\asyncio_manager.py", line 136, in run
    return future.result()
           ^^^^^^^^^^^^^^^
  File "C:\Program Files\WindowsApps\PythonSoftwareFoundation.Python.3.12_3.12.2800.0_x64__qbz5n2kfra8p0\Lib\concurrent\futures\_base.py", line 456, in result
    return self.__get_result()
           ^^^^^^^^^^^^^^^^^^^
  File "C:\Program Files\WindowsApps\PythonSoftwareFoundation.Python.3.12_3.12.2800.0_x64__qbz5n2kfra8p0\Lib\concurrent\futures\_base.py", line 401, in __get_result
    raise self._exception
  File "D:\Code\Machine Learning\indonesian_coconut\venv\Lib\site-packages\wandb\sdk\lib\asyncio_manager.py", line 219, in _wrap
    return await fn()
           ^^^^^^^^^^
  File "D:\Code\Machine Learning\indonesian_coconut\venv\Lib\site-packages\wandb\sdk\lib\service\service_client.py", line 38, in publish
    await self._send_server_request(request)
  File "D:\Code\Machine Learning\indonesian_coconut\venv\Lib\site-packages\wandb\sdk\lib\service\service_client.py", line 64, in _send_server_request
    await self._writer.drain()
  File "C:\Program Files\WindowsApps\PythonSoftwareFoundation.Python.3.12_3.12.2800.0_x64__qbz5n2kfra8p0\Lib\asyncio\streams.py", line 380, in drain
    raise exc
  File "D:\Code\Machine Learning\indonesian_coconut\venv\Lib\site-packages\wandb\sdk\lib\redirect.py", line 662, in _on_write
    cb(written_data)
  File "D:\Code\Machine Learning\indonesian_coconut\venv\Lib\site-packages\wandb\sdk\wandb_run.py", line 2430, in <lambda>
    lambda data: self._console_raw_callback("stdout", data),
                 ^^^^^^^^^^^^^^^^^^^^^^^^^^^^^^^^^^^^^^^^^^
  File "D:\Code\Machine Learning\indonesian_coconut\venv\Lib\site-packages\wandb\sdk\wandb_run.py", line 399, in wrapper
    return func(self, *args, **kwargs)
           ^^^^^^^^^^^^^^^^^^^^^^^^^^^
  File "D:\Code\Machine Learning\indonesian_coconut\venv\Lib\site-packages\wandb\sdk\wandb_run.py", line 457, in wrapper_fn
    return func(self, *args, **kwargs)
           ^^^^^^^^^^^^^^^^^^^^^^^^^^^
  File "D:\Code\Machine Learning\indonesian_coconut\venv\Lib\site-packages\wandb\sdk\wandb_run.py", line 1595, in _console_raw_callback
    self._backend.interface.publish_output_raw(name, data)
  File "D:\Code\Machine Learning\indonesian_coconut\venv\Lib\site-packages\wandb\sdk\interface\interface.py", line 802, in publish_output_raw
    self._publish_output_raw(o)
  File "D:\Code\Machine Learning\indonesian_coconut\venv\Lib\site-packages\wandb\sdk\interface\interface_shared.py", line 37, in _publish_output_raw
    self._publish(rec)
  File "D:\Code\Machine Learning\indonesian_coconut\venv\Lib\site-packages\wandb\sdk\interface\interface_sock.py", line 43, in _publish
    self._asyncer.run(lambda: self._client.publish(request))
  File "D:\Code\Machine Learning\indonesian_coconut\venv\Lib\site-packages\wandb\sdk\lib\asyncio_manager.py", line 136, in run
    return future.result()
           ^^^^^^^^^^^^^^^
  File "C:\Program Files\WindowsApps\PythonSoftwareFoundation.Python.3.12_3.12.2800.0_x64__qbz5n2kfra8p0\Lib\concurrent\futures\_base.py", line 449, in result
    return self.__get_result()
           ^^^^^^^^^^^^^^^^^^^
  File "C:\Program Files\WindowsApps\PythonSoftwareFoundation.Python.3.12_3.12.2800.0_x64__qbz5n2kfra8p0\Lib\concurrent\futures\_base.py", line 401, in __get_result
    raise self._exception
  File "D:\Code\Machine Learning\indonesian_coconut\venv\Lib\site-packages\wandb\sdk\lib\asyncio_manager.py", line 219, in _wrap
    return await fn()
           ^^^^^^^^^^
  File "D:\Code\Machine Learning\indonesian_coconut\venv\Lib\site-packages\wandb\sdk\lib\service\service_client.py", line 38, in publish
    await self._send_server_request(request)
  File "D:\Code\Machine Learning\indonesian_coconut\venv\Lib\site-packages\wandb\sdk\lib\service\service_client.py", line 64, in _send_server_request
    await self._writer.drain()
  File "C:\Program Files\WindowsApps\PythonSoftwareFoundation.Python.3.12_3.12.2800.0_x64__qbz5n2kfra8p0\Lib\asyncio\streams.py", line 380, in drain
    raise exc
  File "D:\Code\Machine Learning\indonesian_coconut\venv\Lib\site-packages\wandb\sdk\lib\service\service_client.py", line 73, in _forward_responses
    while response := await self._read_server_response():
                      ^^^^^^^^^^^^^^^^^^^^^^^^^^^^^^^^^^
  File "D:\Code\Machine Learning\indonesian_coconut\venv\Lib\site-packages\wandb\sdk\lib\service\service_client.py", line 87, in _read_server_response
    header = await self._reader.readexactly(_HEADER_BYTE_INT_LEN)
             ^^^^^^^^^^^^^^^^^^^^^^^^^^^^^^^^^^^^^^^^^^^^^^^^^^^^
  File "C:\Program Files\WindowsApps\PythonSoftwareFoundation.Python.3.12_3.12.2800.0_x64__qbz5n2kfra8p0\Lib\asyncio\streams.py", line 752, in readexactly
    await self._wait_for_data('readexactly')
  File "C:\Program Files\WindowsApps\PythonSoftwareFoundation.Python.3.12_3.12.2800.0_x64__qbz5n2kfra8p0\Lib\asyncio\streams.py", line 545, in _wait_for_data
    await self._waiter
  File "C:\Program Files\WindowsApps\PythonSoftwareFoundation.Python.3.12_3.12.2800.0_x64__qbz5n2kfra8p0\Lib\asyncio\proactor_events.py", line 286, in _loop_reading
    length = fut.result()
             ^^^^^^^^^^^^
  File "C:\Program Files\WindowsApps\PythonSoftwareFoundation.Python.3.12_3.12.2800.0_x64__qbz5n2kfra8p0\Lib\asyncio\windows_events.py", line 803, in _poll
    value = callback(transferred, key, ov)
            ^^^^^^^^^^^^^^^^^^^^^^^^^^^^^^
  File "C:\Program Files\WindowsApps\PythonSoftwareFoundation.Python.3.12_3.12.2800.0_x64__qbz5n2kfra8p0\Lib\asyncio\windows_events.py", line 466, in finish_socket_func
    raise ConnectionResetError(*exc.args)
ConnectionResetError: [WinError 64] The specified network name is no longer available
